<?xml version="1.0" encoding="UTF-8"?>
<!-- Generated by org.testng.reporters.JUnitReportReporter -->
<testsuite hostname="admin-PC" name="com.mock.example.service.testngimpl.test1.TestNgMysql" tests="2" failures="0" timestamp="31 Oct 2020 05:23:14 GMT" time="0.601" errors="1">
  <testcase name="test1" time="0.592" classname="com.mock.example.service.testngimpl.test1.TestNgMysql">
    <error type="java.lang.RuntimeException" message="Timed out waiting for the codeBlock to not throw throwable!">
      <![CDATA[java.lang.RuntimeException: Timed out waiting for the codeBlock to not throw throwable!
	at com.mock.constant.teseng.BaseTestNgPrepare.waitForCodeBlockToNotThrowThrowableAndReturnTrue(BaseTestNgPrepare.java:86)
	at com.mock.constant.teseng.BaseTestNgPrepare.waitForCheckoutResult(BaseTestNgPrepare.java:48)
	at com.mock.example.service.testngimpl.test1.TestNgMysql.test1(TestNgMysql.java:15)
	at sun.reflect.NativeMethodAccessorImpl.invoke0(Native Method)
	at sun.reflect.NativeMethodAccessorImpl.invoke(NativeMethodAccessorImpl.java:62)
	at sun.reflect.DelegatingMethodAccessorImpl.invoke(DelegatingMethodAccessorImpl.java:43)
	at java.lang.reflect.Method.invoke(Method.java:498)
	at org.testng.internal.MethodInvocationHelper.invokeMethod(MethodInvocationHelper.java:86)
	at org.testng.internal.Invoker.invokeMethod(Invoker.java:643)
	at org.testng.internal.Invoker.invokeTestMethod(Invoker.java:820)
	at org.testng.internal.Invoker.invokeTestMethods(Invoker.java:1128)
	at org.testng.internal.TestMethodWorker.invokeTestMethods(TestMethodWorker.java:129)
	at org.testng.internal.TestMethodWorker.run(TestMethodWorker.java:112)
	at org.testng.TestRunner.privateRun(TestRunner.java:782)
	at org.testng.TestRunner.run(TestRunner.java:632)
	at org.testng.SuiteRunner.runTest(SuiteRunner.java:366)
	at org.testng.SuiteRunner.runSequentially(SuiteRunner.java:361)
	at org.testng.SuiteRunner.privateRun(SuiteRunner.java:319)
	at org.testng.SuiteRunner.run(SuiteRunner.java:268)
	at org.testng.SuiteRunnerWorker.runSuite(SuiteRunnerWorker.java:52)
	at org.testng.SuiteRunnerWorker.run(SuiteRunnerWorker.java:86)
	at org.testng.TestNG.runSuitesSequentially(TestNG.java:1244)
	at org.testng.TestNG.runSuitesLocally(TestNG.java:1169)
	at org.testng.TestNG.run(TestNG.java:1064)
	at org.testng.remote.AbstractRemoteTestNG.run(AbstractRemoteTestNG.java:132)
	at org.testng.remote.RemoteTestNG.initAndRun(RemoteTestNG.java:236)
	at org.testng.remote.RemoteTestNG.main(RemoteTestNG.java:81)
Caused by: java.lang.AssertionError: expected [121] but found [12]
	at org.testng.Assert.fail(Assert.java:94)
	at org.testng.Assert.failNotEquals(Assert.java:513)
	at org.testng.Assert.assertEqualsImpl(Assert.java:135)
	at org.testng.Assert.assertEquals(Assert.java:116)
	at org.testng.Assert.assertEquals(Assert.java:190)
	at org.testng.Assert.assertEquals(Assert.java:200)
	at com.mock.example.service.testngimpl.test1.TestNgMysql.lambda$0(TestNgMysql.java:16)
	at com.mock.constant.teseng.BaseTestNgPrepare.lambda$0(BaseTestNgPrepare.java:49)
	at com.mock.constant.teseng.BaseTestNgPrepare.waitForCodeBlockToNotThrowThrowableAndReturnTrue(BaseTestNgPrepare.java:68)
	... 26 more
]]>
    </error>
  </testcase> <!-- test1 -->
  <testcase name="testLambda" time="0.009" classname="com.mock.example.service.testngimpl.test1.TestNgMysql"/>
</testsuite> <!-- com.mock.example.service.testngimpl.test1.TestNgMysql -->
